Halleleluyeigh: {"info":"Welcome to the BitMEX Realtime API.","version":"2019-03-15T21:28:26.000Z","timestamp":"2019-03-16T07:51:37.501Z","docs":"https://www.bitmex.com/app/wsAPI","limit":{"remaining":39}}
Halleleluyeigh: {"success":true,"request":{"op":"authKeyExpires","args":["l_OGpLlK63FsA__81_232atG",1552722697000,"983d83952d2dbdcad3bc8f4c35f0758d934eca1a83e13986101ff92d53cd8604"]}}
Halleleluyeigh: {"success":true,"subscribe":"orderBookL2_25:XBTUSD","request":{"op":"subscribe","args":["orderBookL2_25:XBTUSD"]}}
Halleleluyeigh: {"table":"orderBookL2_25","action":"partial","keys":["symbol","id","side"],"types":{"symbol":"symbol","id":"long","side":"symbol","size":"long","price":"float"},"foreignKeys":{"symbol":"instrument","side":"side"},"attributes":{"symbol":"grouped","id":"sorted"},"filter":{"symbol":"XBTUSD"},"data":[{"symbol":"XBTUSD","id":8799598350,"side":"Sell","size":99351,"price":4016.5},{"symbol":"XBTUSD","id":8799598400,"side":"Sell","size":265921,"price":4016},{"symbol":"XBTUSD","id":8799598450,"side":"Sell","size":89836,"price":4015.5},{"symbol":"XBTUSD","id":8799598500,"side":"Sell","size":245043,"price":4015},{"symbol":"XBTUSD","id":8799598550,"side":"Sell","size":453757,"price":4014.5},{"symbol":"XBTUSD","id":8799598600,"side":"Sell","size":177081,"price":4014},{"symbol":"XBTUSD","id":8799598650,"side":"Sell","size":58041,"price":4013.5},{"symbol":"XBTUSD","id":8799598700,"side":"Sell","size":172692,"price":4013},{"symbol":"XBTUSD","id":8799598750,"side":"Sell","size":488428,"price":4012.5},{"symbol":"XBTUSD","id":8799598800,"side":"Sell","size":267345,"price":4012},{"symbol":"XBTUSD","id":8799598850,"side":"Sell","size":68761,"price":4011.5},{"symbol":"XBTUSD","id":8799598900,"side":"Sell","size":153266,"price":4011},{"symbol":"XBTUSD","id":8799598950,"side":"Sell","size":137914,"price":4010.5},{"symbol":"XBTUSD","id":8799599000,"side":"Sell","size":970447,"price":4010},{"symbol":"XBTUSD","id":8799599050,"side":"Sell","size":955721,"price":4009.5},{"symbol":"XBTUSD","id":8799599100,"side":"Sell","size":139797,"price":4009},{"symbol":"XBTUSD","id":8799599150,"side":"Sell","size":141913,"price":4008.5},{"symbol":"XBTUSD","id":8799599200,"side":"Sell","size":171417,"price":4008},{"symbol":"XBTUSD","id":8799599250,"side":"Sell","size":64990,"price":4007.5},{"symbol":"XBTUSD","id":8799599300,"side":"Sell","size":325582,"price":4007},{"symbol":"XBTUSD","id":8799599350,"side":"Sell","size":61517,"price":4006.5},{"symbol":"XBTUSD","id":8799599400,"side":"Sell","size":148909,"price":4006},{"symbol":"XBTUSD","id":8799599450,"side":"Sell","size":481391,"price":4005.5},{"symbol":"XBTUSD","id":8799599500,"side":"Sell","size":983666,"price":4005},{"symbol":"XBTUSD","id":8799599550,"side":"Sell","size":1188504,"price":4004.5},{"symbol":"XBTUSD","id":8799599600,"side":"Buy","size":1012631,"price":4004},{"symbol":"XBTUSD","id":8799599650,"side":"Buy","size":291364,"price":4003.5},{"symbol":"XBTUSD","id":8799599700,"side":"Buy","size":236690,"price":4003},{"symbol":"XBTUSD","id":8799599750,"side":"Buy","size":499425,"price":4002.5},{"symbol":"XBTUSD","id":8799599800,"side":"Buy","size":232346,"price":4002},{"symbol":"XBTUSD","id":8799599850,"side":"Buy","size":135445,"price":4001.5},{"symbol":"XBTUSD","id":8799599900,"side":"Buy","size":341000,"price":4001},{"symbol":"XBTUSD","id":8799599950,"side":"Buy","size":818539,"price":4000.5},{"symbol":"XBTUSD","id":8799600000,"side":"Buy","size":1458846,"price":4000},{"symbol":"XBTUSD","id":8799600050,"side":"Buy","size":41948,"price":3999.5},{"symbol":"XBTUSD","id":8799600100,"side":"Buy","size":186993,"price":3999},{"symbol":"XBTUSD","id":8799600150,"side":"Buy","size":335692,"price":3998.5},{"symbol":"XBTUSD","id":8799600200,"side":"Buy","size":289985,"price":3998},{"symbol":"XBTUSD","id":8799600250,"side":"Buy","size":281571,"price":3997.5},{"symbol":"XBTUSD","id":8799600300,"side":"Buy","size":278937,"price":3997},{"symbol":"XBTUSD","id":8799600350,"side":"Buy","size":187134,"price":3996.5},{"symbol":"XBTUSD","id":8799600400,"side":"Buy","size":701225,"price":3996},{"symbol":"XBTUSD","id":8799600450,"side":"Buy","size":145839,"price":3995.5},{"symbol":"XBTUSD","id":8799600500,"side":"Buy","size":474388,"price":3995},{"symbol":"XBTUSD","id":8799600550,"side":"Buy","size":66681,"price":3994.5},{"symbol":"XBTUSD","id":8799600600,"side":"Buy","size":253507,"price":3994},{"symbol":"XBTUSD","id":8799600650,"side":"Buy","size":138241,"price":3993.5},{"symbol":"XBTUSD","id":8799600700,"side":"Buy","size":120114,"price":3993},{"symbol":"XBTUSD","id":8799600750,"side":"Buy","size":217042,"price":3992.5},{"symbol":"XBTUSD","id":8799600800,"side":"Buy","size":572569,"price":3992}]}
Halleleluyeigh: {"table":"orderBookL2_25","action":"update","data":[{"symbol":"XBTUSD","id":8799599400,"side":"Sell","size":148842}]}
Halleleluyeigh: {"table":"orderBookL2_25","action":"update","data":[{"symbol":"XBTUSD","id":8799599150,"side":"Sell","size":141863},{"symbol":"XBTUSD","id":8799599300,"side":"Sell","size":325632}]}
Halleleluyeigh: {"table":"orderBookL2_25","action":"update","data":[{"symbol":"XBTUSD","id":8799599000,"side":"Sell","size":970947},{"symbol":"XBTUSD","id":8799599050,"side":"Sell","size":955221},{"symbol":"XBTUSD","id":8799599100,"side":"Sell","size":140797},{"symbol":"XBTUSD","id":8799599150,"side":"Sell","size":140863}]}
Halleleluyeigh: {"table":"orderBookL2_25","action":"update","data":[{"symbol":"XBTUSD","id":8799599450,"side":"Sell","size":484079}]}
Halleleluyeigh: {"table":"orderBookL2_25","action":"update","data":[{"symbol":"XBTUSD","id":8799598750,"side":"Sell","size":424228},{"symbol":"XBTUSD","id":8799598800,"side":"Sell","size":331537}]}
Halleleluyeigh: {"table":"orderBookL2_25","action":"update","data":[{"symbol":"XBTUSD","id":8799599600,"side":"Buy","size":1012633},{"symbol":"XBTUSD","id":8799599650,"side":"Buy","size":291366}]}
Halleleluyeigh: {"table":"orderBookL2_25","action":"update","data":[{"symbol":"XBTUSD","id":8799599500,"side":"Sell","size":983667},{"symbol":"XBTUSD","id":8799599550,"side":"Sell","size":1188505}]}
Halleleluyeigh: {"table":"orderBookL2_25","action":"update","data":[{"symbol":"XBTUSD","id":8799598400,"side":"Sell","size":265446},{"symbol":"XBTUSD","id":8799599550,"side":"Sell","size":1190505}]}
Halleleluyeigh: {"table":"orderBookL2_25","action":"update","data":[{"symbol":"XBTUSD","id":8799599650,"side":"Buy","size":291336},{"symbol":"XBTUSD","id":8799599750,"side":"Buy","size":499445},{"symbol":"XBTUSD","id":8799599850,"side":"Buy","size":135475}]}
Halleleluyeigh: {"table":"orderBookL2_25","action":"update","data":[{"symbol":"XBTUSD","id":8799599600,"side":"Buy","size":1013633},{"symbol":"XBTUSD","id":8799599650,"side":"Buy","size":290336}]}
Halleleluyeigh: {"table":"orderBookL2_25","action":"update","data":[{"symbol":"XBTUSD","id":8799599450,"side":"Sell","size":480079},{"symbol":"XBTUSD","id":8799599600,"side":"Buy","size":1013683}]}
Halleleluyeigh: {"table":"orderBookL2_25","action":"update","data":[{"symbol":"XBTUSD","id":8799598900,"side":"Sell","size":152813},{"symbol":"XBTUSD","id":8799599800,"side":"Buy","size":214446},{"symbol":"XBTUSD","id":8799599900,"side":"Buy","size":340628},{"symbol":"XBTUSD","id":8799600200,"side":"Buy","size":289799},{"symbol":"XBTUSD","id":8799600500,"side":"Buy","size":474202}]}
Halleleluyeigh: {"table":"orderBookL2_25","action":"update","data":[{"symbol":"XBTUSD","id":8799599550,"side":"Sell","size":1190484}]}
Halleleluyeigh: {"table":"orderBookL2_25","action":"update","data":[{"symbol":"XBTUSD","id":8799600000,"side":"Buy","size":1457846},{"symbol":"XBTUSD","id":8799600050,"side":"Buy","size":42948}]}
Halleleluyeigh: {"table":"orderBookL2_25","action":"update","data":[{"symbol":"XBTUSD","id":8799599550,"side":"Sell","size":1190428}]}
Halleleluyeigh: {"table":"orderBookL2_25","action":"update","data":[{"symbol":"XBTUSD","id":8799599550,"side":"Sell","size":1188928},{"symbol":"XBTUSD","id":8799599800,"side":"Buy","size":214246},{"symbol":"XBTUSD","id":8799600650,"side":"Buy","size":137141}]}
Halleleluyeigh: {"table":"orderBookL2_25","action":"update","data":[{"symbol":"XBTUSD","id":8799599550,"side":"Sell","size":1196468},{"symbol":"XBTUSD","id":8799599900,"side":"Buy","size":341128},{"symbol":"XBTUSD","id":8799599950,"side":"Buy","size":818039},{"symbol":"XBTUSD","id":8799600650,"side":"Buy","size":134941}]}
Halleleluyeigh: {"table":"orderBookL2_25","action":"update","data":[{"symbol":"XBTUSD","id":8799598900,"side":"Sell","size":153513},{"symbol":"XBTUSD","id":8799599500,"side":"Sell","size":982967},{"symbol":"XBTUSD","id":8799600650,"side":"Buy","size":136041}]}
Halleleluyeigh: {"table":"orderBookL2_25","action":"update","data":[{"symbol":"XBTUSD","id":8799598900,"side":"Sell","size":153966},{"symbol":"XBTUSD","id":8799599900,"side":"Buy","size":341500},{"symbol":"XBTUSD","id":8799600200,"side":"Buy","size":289985},{"symbol":"XBTUSD","id":8799600500,"side":"Buy","size":474388},{"symbol":"XBTUSD","id":8799600650,"side":"Buy","size":137141}]}
Halleleluyeigh: {"table":"orderBookL2_25","action":"update","data":[{"symbol":"XBTUSD","id":8799600650,"side":"Buy","size":138241}]}
Halleleluyeigh: {"table":"orderBookL2_25","action":"update","data":[{"symbol":"XBTUSD","id":8799599600,"side":"Buy","size":1013972},{"symbol":"XBTUSD","id":8799599950,"side":"Buy","size":768039}]}
Halleleluyeigh: {"table":"orderBookL2_25","action":"update","data":[{"symbol":"XBTUSD","id":8799599450,"side":"Sell","size":480068},{"symbol":"XBTUSD","id":8799599500,"side":"Sell","size":982978},{"symbol":"XBTUSD","id":8799599550,"side":"Sell","size":1194751},{"symbol":"XBTUSD","id":8799599600,"side":"Buy","size":991472},{"symbol":"XBTUSD","id":8799599800,"side":"Buy","size":210246}]}
Halleleluyeigh: {"table":"orderBookL2_25","action":"update","data":[{"symbol":"XBTUSD","id":8799599550,"side":"Sell","size":1198463},{"symbol":"XBTUSD","id":8799599800,"side":"Buy","size":206246}]}
Halleleluyeigh: {"table":"orderBookL2_25","action":"update","data":[{"symbol":"XBTUSD","id":8799598550,"side":"Sell","size":442182},{"symbol":"XBTUSD","id":8799598600,"side":"Sell","size":188945},{"symbol":"XBTUSD","id":8799598900,"side":"Sell","size":151566},{"symbol":"XBTUSD","id":8799599100,"side":"Sell","size":135797},{"symbol":"XBTUSD","id":8799599200,"side":"Sell","size":171437},{"symbol":"XBTUSD","id":8799599550,"side":"Sell","size":707389}]}
Halleleluyeigh: {"table":"orderBookL2_25","action":"update","data":[{"symbol":"XBTUSD","id":8799598700,"side":"Sell","size":236900},{"symbol":"XBTUSD","id":8799598800,"side":"Sell","size":267345},{"symbol":"XBTUSD","id":8799599450,"side":"Sell","size":485068},{"symbol":"XBTUSD","id":8799599500,"side":"Sell","size":977978},{"symbol":"XBTUSD","id":8799599550,"side":"Sell","size":671303},{"symbol":"XBTUSD","id":8799599600,"side":"Buy","size":996474},{"symbol":"XBTUSD","id":8799599650,"side":"Buy","size":308616},{"symbol":"XBTUSD","id":8799599750,"side":"Buy","size":477667}]}
Halleleluyeigh: {"table":"orderBookL2_25","action":"update","data":[{"symbol":"XBTUSD","id":8799599500,"side":"Sell","size":977979},{"symbol":"XBTUSD","id":8799599550,"side":"Sell","size":668304}]}
Halleleluyeigh: {"table":"orderBookL2_25","action":"update","data":[{"symbol":"XBTUSD","id":8799598600,"side":"Sell","size":187413},{"symbol":"XBTUSD","id":8799599100,"side":"Sell","size":132733},{"symbol":"XBTUSD","id":8799599550,"side":"Sell","size":665304},{"symbol":"XBTUSD","id":8799599800,"side":"Buy","size":206046}]}
Halleleluyeigh: {"table":"orderBookL2_25","action":"update","data":[{"symbol":"XBTUSD","id":8799598900,"side":"Sell","size":151174},{"symbol":"XBTUSD","id":8799599550,"side":"Sell","size":663304},{"symbol":"XBTUSD","id":8799599600,"side":"Buy","size":1091474},{"symbol":"XBTUSD","id":8799599750,"side":"Buy","size":478167},{"symbol":"XBTUSD","id":8799599900,"side":"Buy","size":341014},{"symbol":"XBTUSD","id":8799600200,"side":"Buy","size":289742},{"symbol":"XBTUSD","id":8799600500,"side":"Buy","size":474145}]}
Halleleluyeigh: {"table":"orderBookL2_25","action":"update","data":[{"symbol":"XBTUSD","id":8799599550,"side":"Sell","size":653304}]}
Halleleluyeigh: {"table":"orderBookL2_25","action":"update","data":[{"symbol":"XBTUSD","id":8799599200,"side":"Sell","size":172737}]}
Halleleluyeigh: {"table":"orderBookL2_25","action":"update","data":[{"symbol":"XBTUSD","id":8799598950,"side":"Sell","size":147914},{"symbol":"XBTUSD","id":8799599150,"side":"Sell","size":145863},{"symbol":"XBTUSD","id":8799600000,"side":"Buy","size":1458846},{"symbol":"XBTUSD","id":8799600050,"side":"Buy","size":41948}]}
Halleleluyeigh: {"table":"orderBookL2_25","action":"update","data":[{"symbol":"XBTUSD","id":8799599900,"side":"Buy","size":341514},{"symbol":"XBTUSD","id":8799600050,"side":"Buy","size":41448}]}
Halleleluyeigh: {"table":"orderBookL2_25","action":"update","data":[{"symbol":"XBTUSD","id":8799598700,"side":"Sell","size":237000},{"symbol":"XBTUSD","id":8799598750,"side":"Sell","size":424128},{"symbol":"XBTUSD","id":8799598900,"side":"Sell","size":156174},{"symbol":"XBTUSD","id":8799599000,"side":"Sell","size":965947},{"symbol":"XBTUSD","id":8799599150,"side":"Sell","size":147863},{"symbol":"XBTUSD","id":8799599200,"side":"Sell","size":170737},{"symbol":"XBTUSD","id":8799599300,"side":"Sell","size":330632},{"symbol":"XBTUSD","id":8799599400,"side":"Sell","size":143842},{"symbol":"XBTUSD","id":8799599850,"side":"Buy","size":135575},{"symbol":"XBTUSD","id":8799599900,"side":"Buy","size":341614},{"symbol":"XBTUSD","id":8799599950,"side":"Buy","size":767939},{"symbol":"XBTUSD","id":8799600000,"side":"Buy","size":1464846},{"symbol":"XBTUSD","id":8799600050,"side":"Buy","size":40448},{"symbol":"XBTUSD","id":8799600100,"side":"Buy","size":181993},{"symbol":"XBTUSD","id":8799600300,"side":"Buy","size":280937},{"symbol":"XBTUSD","id":8799600400,"side":"Buy","size":704225},{"symbol":"XBTUSD","id":8799600600,"side":"Buy","size":248507}]}
Halleleluyeigh: {"table":"orderBookL2_25","action":"update","data":[{"symbol":"XBTUSD","id":8799599600,"side":"Buy","size":1091674},{"symbol":"XBTUSD","id":8799600050,"side":"Buy","size":43148},{"symbol":"XBTUSD","id":8799600100,"side":"Buy","size":179293}]}
Halleleluyeigh: {"table":"orderBookL2_25","action":"update","data":[{"symbol":"XBTUSD","id":8799598900,"side":"Sell","size":155882},{"symbol":"XBTUSD","id":8799599900,"side":"Buy","size":341252},{"symbol":"XBTUSD","id":8799600200,"side":"Buy","size":289561},{"symbol":"XBTUSD","id":8799600500,"side":"Buy","size":473964}]}
Halleleluyeigh: {"table":"orderBookL2_25","action":"update","data":[{"symbol":"XBTUSD","id":8799598600,"side":"Sell","size":188945},{"symbol":"XBTUSD","id":8799599100,"side":"Sell","size":135797},{"symbol":"XBTUSD","id":8799599200,"side":"Sell","size":243491}]}
Halleleluyeigh: {"table":"orderBookL2_25","action":"update","data":[{"symbol":"XBTUSD","id":8799598700,"side":"Sell","size":172792},{"symbol":"XBTUSD","id":8799598750,"side":"Sell","size":488328},{"symbol":"XBTUSD","id":8799598900,"side":"Sell","size":156274},{"symbol":"XBTUSD","id":8799599900,"side":"Buy","size":341738},{"symbol":"XBTUSD","id":8799600100,"side":"Buy","size":209293},{"symbol":"XBTUSD","id":8799600200,"side":"Buy","size":289804},{"symbol":"XBTUSD","id":8799600500,"side":"Buy","size":474207}]}
Halleleluyeigh: {"table":"orderBookL2_25","action":"update","data":[{"symbol":"XBTUSD","id":8799599550,"side":"Sell","size":599182},{"symbol":"XBTUSD","id":8799599600,"side":"Buy","size":1091686}]}
Halleleluyeigh: {"table":"orderBookL2_25","action":"update","data":[{"symbol":"XBTUSD","id":8799599550,"side":"Sell","size":599209}]}
Halleleluyeigh: {"table":"orderBookL2_25","action":"update","data":[{"symbol":"XBTUSD","id":8799599550,"side":"Sell","size":595497}]}
Halleleluyeigh: {"table":"orderBookL2_25","action":"update","data":[{"symbol":"XBTUSD","id":8799599650,"side":"Buy","size":336207},{"symbol":"XBTUSD","id":8799599700,"side":"Buy","size":211690}]}
Halleleluyeigh: {"table":"orderBookL2_25","action":"update","data":[{"symbol":"XBTUSD","id":8799598900,"side":"Sell","size":151274},{"symbol":"XBTUSD","id":8799599300,"side":"Sell","size":325632},{"symbol":"XBTUSD","id":8799600000,"side":"Buy","size":1459846},{"symbol":"XBTUSD","id":8799600300,"side":"Buy","size":278937},{"symbol":"XBTUSD","id":8799600350,"side":"Buy","size":189134},{"symbol":"XBTUSD","id":8799600400,"side":"Buy","size":699225}]}
Halleleluyeigh: {"table":"orderBookL2_25","action":"update","data":[{"symbol":"XBTUSD","id":8799599000,"side":"Sell","size":970947},{"symbol":"XBTUSD","id":8799599200,"side":"Sell","size":184601},{"symbol":"XBTUSD","id":8799599250,"side":"Sell","size":127697},{"symbol":"XBTUSD","id":8799599400,"side":"Sell","size":148842},{"symbol":"XBTUSD","id":8799600100,"side":"Buy","size":214293},{"symbol":"XBTUSD","id":8799600500,"side":"Buy","size":479207}]}
Halleleluyeigh: {"table":"orderBookL2_25","action":"update","data":[{"symbol":"XBTUSD","id":8799599550,"side":"Sell","size":605537},{"symbol":"XBTUSD","id":8799600550,"side":"Buy","size":65481},{"symbol":"XBTUSD","id":8799600650,"side":"Buy","size":136041}]}
Halleleluyeigh: {"table":"orderBookL2_25","action":"update","data":[{"symbol":"XBTUSD","id":8799600200,"side":"Buy","size":285104},{"symbol":"XBTUSD","id":8799600550,"side":"Buy","size":66681},{"symbol":"XBTUSD","id":8799600600,"side":"Buy","size":243807},{"symbol":"XBTUSD","id":8799600650,"side":"Buy","size":133341},{"symbol":"XBTUSD","id":8799600700,"side":"Buy","size":117414},{"symbol":"XBTUSD","id":8799600750,"side":"Buy","size":215042},{"symbol":"XBTUSD","id":8799600800,"side":"Buy","size":570569}]}
Halleleluyeigh: {"table":"orderBookL2_25","action":"update","data":[{"symbol":"XBTUSD","id":8799598900,"side":"Sell","size":151566},{"symbol":"XBTUSD","id":8799599750,"side":"Buy","size":478417},{"symbol":"XBTUSD","id":8799599800,"side":"Buy","size":205796},{"symbol":"XBTUSD","id":8799599900,"side":"Buy","size":342100},{"symbol":"XBTUSD","id":8799600200,"side":"Buy","size":285985},{"symbol":"XBTUSD","id":8799600500,"side":"Buy","size":479388},{"symbol":"XBTUSD","id":8799600600,"side":"Buy","size":244507},{"symbol":"XBTUSD","id":8799600650,"side":"Buy","size":136041},{"symbol":"XBTUSD","id":8799600700,"side":"Buy","size":120114},{"symbol":"XBTUSD","id":8799600750,"side":"Buy","size":213042},{"symbol":"XBTUSD","id":8799600800,"side":"Buy","size":568569}]}
Halleleluyeigh: {"table":"orderBookL2_25","action":"update","data":[{"symbol":"XBTUSD","id":8799599400,"side":"Sell","size":232915},{"symbol":"XBTUSD","id":8799599500,"side":"Sell","size":891204},{"symbol":"XBTUSD","id":8799600700,"side":"Buy","size":122114},{"symbol":"XBTUSD","id":8799600750,"side":"Buy","size":215042}]}
Halleleluyeigh: {"table":"orderBookL2_25","action":"update","data":[{"symbol":"XBTUSD","id":8799598450,"side":"Sell","size":89664},{"symbol":"XBTUSD","id":8799599550,"side":"Sell","size":605252},{"symbol":"XBTUSD","id":8799600200,"side":"Buy","size":287985},{"symbol":"XBTUSD","id":8799600600,"side":"Buy","size":246507}]}
Halleleluyeigh: {"table":"orderBookL2_25","action":"update","data":[{"symbol":"XBTUSD","id":8799599550,"side":"Sell","size":627984},{"symbol":"XBTUSD","id":8799600100,"side":"Buy","size":214288},{"symbol":"XBTUSD","id":8799600150,"side":"Buy","size":335697},{"symbol":"XBTUSD","id":8799600200,"side":"Buy","size":289985},{"symbol":"XBTUSD","id":8799600250,"side":"Buy","size":279371},{"symbol":"XBTUSD","id":8799600600,"side":"Buy","size":246307},{"symbol":"XBTUSD","id":8799600650,"side":"Buy","size":134941},{"symbol":"XBTUSD","id":8799600700,"side":"Buy","size":124114},{"symbol":"XBTUSD","id":8799600750,"side":"Buy","size":214842},{"symbol":"XBTUSD","id":8799600800,"side":"Buy","size":566369}]}
Halleleluyeigh: {"table":"orderBookL2_25","action":"update","data":[{"symbol":"XBTUSD","id":8799599800,"side":"Buy","size":206087},{"symbol":"XBTUSD","id":8799599850,"side":"Buy","size":135284},{"symbol":"XBTUSD","id":8799599900,"side":"Buy","size":342600},{"symbol":"XBTUSD","id":8799599950,"side":"Buy","size":767439},{"symbol":"XBTUSD","id":8799600250,"side":"Buy","size":274971},{"symbol":"XBTUSD","id":8799600600,"side":"Buy","size":241907},{"symbol":"XBTUSD","id":8799600650,"side":"Buy","size":136041},{"symbol":"XBTUSD","id":8799600750,"side":"Buy","size":210442},{"symbol":"XBTUSD","id":8799600800,"side":"Buy","size":561969}]}
Halleleluyeigh: {"table":"orderBookL2_25","action":"update","data":[{"symbol":"XBTUSD","id":8799599550,"side":"Sell","size":628051},{"symbol":"XBTUSD","id":8799599650,"side":"Buy","size":336297},{"symbol":"XBTUSD","id":8799599700,"side":"Buy","size":211600},{"symbol":"XBTUSD","id":8799600650,"side":"Buy","size":137141},{"symbol":"XBTUSD","id":8799600750,"side":"Buy","size":212642}]}
Halleleluyeigh: {"table":"orderBookL2_25","action":"update","data":[{"symbol":"XBTUSD","id":8799599600,"side":"Buy","size":1091688},{"symbol":"XBTUSD","id":8799599650,"side":"Buy","size":336299},{"symbol":"XBTUSD","id":8799600150,"side":"Buy","size":351691},{"symbol":"XBTUSD","id":8799600200,"side":"Buy","size":276193},{"symbol":"XBTUSD","id":8799600350,"side":"Buy","size":221106},{"symbol":"XBTUSD","id":8799600400,"side":"Buy","size":667257},{"symbol":"XBTUSD","id":8799600600,"side":"Buy","size":244107},{"symbol":"XBTUSD","id":8799600750,"side":"Buy","size":276522}]}
Halleleluyeigh: {"table":"orderBookL2_25","action":"update","data":[{"symbol":"XBTUSD","id":8799598450,"side":"Sell","size":89492},{"symbol":"XBTUSD","id":8799598650,"side":"Sell","size":122257},{"symbol":"XBTUSD","id":8799598750,"side":"Sell","size":424128},{"symbol":"XBTUSD","id":8799598950,"side":"Sell","size":137914},{"symbol":"XBTUSD","id":8799599150,"side":"Sell","size":142863},{"symbol":"XBTUSD","id":8799599500,"side":"Sell","size":891205},{"symbol":"XBTUSD","id":8799599550,"side":"Sell","size":628052},{"symbol":"XBTUSD","id":8799600000,"side":"Buy","size":1459835},{"symbol":"XBTUSD","id":8799600200,"side":"Buy","size":278393},{"symbol":"XBTUSD","id":8799600600,"side":"Buy","size":246307},{"symbol":"XBTUSD","id":8799600800,"side":"Buy","size":564169}]}
Halleleluyeigh: {"table":"orderBookL2_25","action":"update","data":[{"symbol":"XBTUSD","id":8799598900,"side":"Sell","size":151282},{"symbol":"XBTUSD","id":8799599900,"side":"Buy","size":342248},{"symbol":"XBTUSD","id":8799600200,"side":"Buy","size":278217},{"symbol":"XBTUSD","id":8799600500,"side":"Buy","size":479212}]}
Halleleluyeigh: {"table":"orderBookL2_25","action":"update","data":[{"symbol":"XBTUSD","id":8799599850,"side":"Buy","size":136284},{"symbol":"XBTUSD","id":8799600000,"side":"Buy","size":1458835},{"symbol":"XBTUSD","id":8799600200,"side":"Buy","size":280417},{"symbol":"XBTUSD","id":8799600600,"side":"Buy","size":248507},{"symbol":"XBTUSD","id":8799600650,"side":"Buy","size":138241},{"symbol":"XBTUSD","id":8799600750,"side":"Buy","size":278722},{"symbol":"XBTUSD","id":8799600800,"side":"Buy","size":568569}]}
Halleleluyeigh: {"table":"orderBookL2_25","action":"update","data":[{"symbol":"XBTUSD","id":8799599500,"side":"Sell","size":775202},{"symbol":"XBTUSD","id":8799600750,"side":"Buy","size":280922}]}
Halleleluyeigh: {"table":"orderBookL2_25","action":"update","data":[{"symbol":"XBTUSD","id":8799598950,"side":"Sell","size":141514},{"symbol":"XBTUSD","id":8799599100,"side":"Sell","size":140797}]}
Halleleluyeigh: {"table":"orderBookL2_25","action":"update","data":[{"symbol":"XBTUSD","id":8799599100,"side":"Sell","size":138797},{"symbol":"XBTUSD","id":8799599200,"side":"Sell","size":186601}]}
Halleleluyeigh: {"table":"orderBookL2_25","action":"update","data":[{"symbol":"XBTUSD","id":8799599100,"side":"Sell","size":137297},{"symbol":"XBTUSD","id":8799599150,"side":"Sell","size":145751},{"symbol":"XBTUSD","id":8799600600,"side":"Buy","size":247584}]}
Halleleluyeigh: {"table":"orderBookL2_25","action":"update","data":[{"symbol":"XBTUSD","id":8799598950,"side":"Sell","size":137464},{"symbol":"XBTUSD","id":8799600000,"side":"Buy","size":1459758}]}
Halleleluyeigh: {"table":"orderBookL2_25","action":"update","data":[{"symbol":"XBTUSD","id":8799599550,"side":"Sell","size":627395},{"symbol":"XBTUSD","id":8799600500,"side":"Buy","size":476324}]}
Halleleluyeigh: {"table":"orderBookL2_25","action":"update","data":[{"symbol":"XBTUSD","id":8799600050,"side":"Buy","size":46036}]}
Halleleluyeigh: {"table":"orderBookL2_25","action":"update","data":[{"symbol":"XBTUSD","id":8799599400,"side":"Sell","size":276949},{"symbol":"XBTUSD","id":8799599500,"side":"Sell","size":730278},{"symbol":"XBTUSD","id":8799599750,"side":"Buy","size":478583},{"symbol":"XBTUSD","id":8799599800,"side":"Buy","size":205921}]}
Halleleluyeigh: {"table":"orderBookL2_25","action":"update","data":[{"symbol":"XBTUSD","id":8799598900,"side":"Sell","size":151566},{"symbol":"XBTUSD","id":8799599900,"side":"Buy","size":342600},{"symbol":"XBTUSD","id":8799600200,"side":"Buy","size":280593},{"symbol":"XBTUSD","id":8799600500,"side":"Buy","size":476500}]}
Halleleluyeigh: {"table":"orderBookL2_25","action":"update","data":[{"symbol":"XBTUSD","id":8799599450,"side":"Sell","size":485057},{"symbol":"XBTUSD","id":8799599500,"side":"Sell","size":730289},{"symbol":"XBTUSD","id":8799599600,"side":"Buy","size":1118210},{"symbol":"XBTUSD","id":8799599800,"side":"Buy","size":206921},{"symbol":"XBTUSD","id":8799600000,"side":"Buy","size":1458758}]}
Halleleluyeigh: {"table":"orderBookL2_25","action":"update","data":[{"symbol":"XBTUSD","id":8799598650,"side":"Sell","size":58041},{"symbol":"XBTUSD","id":8799599250,"side":"Sell","size":132149},{"symbol":"XBTUSD","id":8799599350,"side":"Sell","size":29465},{"symbol":"XBTUSD","id":8799599450,"side":"Sell","size":517090},{"symbol":"XBTUSD","id":8799599500,"side":"Sell","size":730300},{"symbol":"XBTUSD","id":8799599950,"side":"Buy","size":768439},{"symbol":"XBTUSD","id":8799600000,"side":"Buy","size":1457758},{"symbol":"XBTUSD","id":8799600100,"side":"Buy","size":206290},{"symbol":"XBTUSD","id":8799600150,"side":"Buy","size":335697},{"symbol":"XBTUSD","id":8799600200,"side":"Buy","size":288589},{"symbol":"XBTUSD","id":8799600300,"side":"Buy","size":294925},{"symbol":"XBTUSD","id":8799600350,"side":"Buy","size":189134},{"symbol":"XBTUSD","id":8799600550,"side":"Buy","size":98637},{"symbol":"XBTUSD","id":8799600600,"side":"Buy","size":243147},{"symbol":"XBTUSD","id":8799600750,"side":"Buy","size":217042},{"symbol":"XBTUSD","id":8799600800,"side":"Buy","size":504697}]}
Halleleluyeigh: {"table":"orderBookL2_25","action":"update","data":[{"symbol":"XBTUSD","id":8799598500,"side":"Sell","size":245028},{"symbol":"XBTUSD","id":8799598550,"side":"Sell","size":442197},{"symbol":"XBTUSD","id":8799599000,"side":"Sell","size":970932},{"symbol":"XBTUSD","id":8799599050,"side":"Sell","size":955236},{"symbol":"XBTUSD","id":8799599500,"side":"Sell","size":730285},{"symbol":"XBTUSD","id":8799599550,"side":"Sell","size":627410},{"symbol":"XBTUSD","id":8799600100,"side":"Buy","size":206295},{"symbol":"XBTUSD","id":8799600150,"side":"Buy","size":335692}]}
Halleleluyeigh: {"table":"orderBookL2_25","action":"update","data":[{"symbol":"XBTUSD","id":8799598950,"side":"Sell","size":133864},{"symbol":"XBTUSD","id":8799599100,"side":"Sell","size":132297},{"symbol":"XBTUSD","id":8799599600,"side":"Buy","size":1112232},{"symbol":"XBTUSD","id":8799599750,"side":"Buy","size":478833},{"symbol":"XBTUSD","id":8799599800,"side":"Buy","size":206671},{"symbol":"XBTUSD","id":8799599850,"side":"Buy","size":137534},{"symbol":"XBTUSD","id":8799599900,"side":"Buy","size":341850},{"symbol":"XBTUSD","id":8799599950,"side":"Buy","size":768428},{"symbol":"XBTUSD","id":8799600000,"side":"Buy","size":1457258},{"symbol":"XBTUSD","id":8799600050,"side":"Buy","size":43336},{"symbol":"XBTUSD","id":8799600100,"side":"Buy","size":176295}]}
Halleleluyeigh: {"table":"orderBookL2_25","action":"update","data":[{"symbol":"XBTUSD","id":8799599450,"side":"Sell","size":517069},{"symbol":"XBTUSD","id":8799599500,"side":"Sell","size":730306},{"symbol":"XBTUSD","id":8799599600,"side":"Buy","size":1109782},{"symbol":"XBTUSD","id":8799600000,"side":"Buy","size":1459958}]}
Halleleluyeigh: {"table":"orderBookL2_25","action":"update","data":[{"symbol":"XBTUSD","id":8799599350,"side":"Sell","size":30465},{"symbol":"XBTUSD","id":8799599500,"side":"Sell","size":680306},{"symbol":"XBTUSD","id":8799599550,"side":"Sell","size":677410},{"symbol":"XBTUSD","id":8799600050,"side":"Buy","size":73336}]}
Halleleluyeigh: {"table":"orderBookL2_25","action":"update","data":[{"symbol":"XBTUSD","id":8799599550,"side":"Sell","size":677403},{"symbol":"XBTUSD","id":8799599600,"side":"Buy","size":1109742},{"symbol":"XBTUSD","id":8799600700,"side":"Buy","size":123614},{"symbol":"XBTUSD","id":8799600800,"side":"Buy","size":505197}]}
Halleleluyeigh: {"table":"orderBookL2_25","action":"update","data":[{"symbol":"XBTUSD","id":8799599600,"side":"Buy","size":1109740},{"symbol":"XBTUSD","id":8799600400,"side":"Buy","size":666178}]}
Halleleluyeigh: {"table":"orderBookL2_25","action":"update","data":[{"symbol":"XBTUSD","id":8799600150,"side":"Buy","size":332992},{"symbol":"XBTUSD","id":8799600200,"side":"Buy","size":283189},{"symbol":"XBTUSD","id":8799600400,"side":"Buy","size":667257},{"symbol":"XBTUSD","id":8799600600,"side":"Buy","size":240447},{"symbol":"XBTUSD","id":8799600650,"side":"Buy","size":135541},{"symbol":"XBTUSD","id":8799600700,"side":"Buy","size":120914}]}
Halleleluyeigh: {"table":"orderBookL2_25","action":"update","data":[{"symbol":"XBTUSD","id":8799599550,"side":"Sell","size":673974},{"symbol":"XBTUSD","id":8799599600,"side":"Buy","size":1127337},{"symbol":"XBTUSD","id":8799599650,"side":"Buy","size":336301},{"symbol":"XBTUSD","id":8799600100,"side":"Buy","size":178995},{"symbol":"XBTUSD","id":8799600150,"side":"Buy","size":336392},{"symbol":"XBTUSD","id":8799600200,"side":"Buy","size":279189},{"symbol":"XBTUSD","id":8799600250,"side":"Buy","size":270971},{"symbol":"XBTUSD","id":8799600550,"side":"Buy","size":101337},{"symbol":"XBTUSD","id":8799600600,"side":"Buy","size":239147},{"symbol":"XBTUSD","id":8799600650,"side":"Buy","size":138241},{"symbol":"XBTUSD","id":8799600700,"side":"Buy","size":116914},{"symbol":"XBTUSD","id":8799600750,"side":"Buy","size":213042}]}
Halleleluyeigh: {"table":"orderBookL2_25","action":"update","data":[{"symbol":"XBTUSD","id":8799599000,"side":"Sell","size":1099252},{"symbol":"XBTUSD","id":8799599250,"side":"Sell","size":127697},{"symbol":"XBTUSD","id":8799599350,"side":"Sell","size":62517},{"symbol":"XBTUSD","id":8799599450,"side":"Sell","size":485025},{"symbol":"XBTUSD","id":8799599500,"side":"Sell","size":680307},{"symbol":"XBTUSD","id":8799599550,"side":"Sell","size":673975},{"symbol":"XBTUSD","id":8799599600,"side":"Buy","size":1129348},{"symbol":"XBTUSD","id":8799600150,"side":"Buy","size":327792},{"symbol":"XBTUSD","id":8799600200,"side":"Buy","size":272589},{"symbol":"XBTUSD","id":8799600250,"side":"Buy","size":264371},{"symbol":"XBTUSD","id":8799600600,"side":"Buy","size":232547},{"symbol":"XBTUSD","id":8799600750,"side":"Buy","size":206442},{"symbol":"XBTUSD","id":8799600800,"side":"Buy","size":498597}]}
